Workbook

Sheet DataPublished
A1: Samit Member Name | B1: Assigned Person | C1: Mobile Number | D1: Status | E1: Registered | F1: Samiti Member Phone Number | G1: Remarks | H1: Address
A2: Shri Narayanji Chandak | B2: Sandeep Subhash Agiwal | C2: 9821381810 | D2: =_xlfn.IFNA(VLOOKUP(C2,CallLog_Latest!A:H,7,FALSE),"Not Called") -> Not Called | E2: =IF(ISNA(VLOOKUP(C2,Registration!A:A,1,FALSE)),"Not Registered","Registered") -> Not Registered | F2: =VLOOKUP(A2,Sheet1!A:B,2,FALSE) -> 9326379737 | G2: =_xlfn.IFNA(VLOOKUP(C2,CallLog_Latest!A:H,8,FALSE),"") | H2: =VLOOKUP(C2,[1]Sheet1!$F:$H,3,FALSE) -> Galaxy CHSL. B-205, Mith Chowky, Marve Road, Malad (W
A3: Shri Manojji Laddha | B3: Anand Jugalkishor Asawa | C3: 9324420871 | D3: =_xlfn.IFNA(VLOOKUP(C3,CallLog_Latest!A:H,7,FALSE),"Not Called") -> Not Called | E3: =IF(ISNA(VLOOKUP(C3,Registration!A:A,1,FALSE)),"Not Registered","Registered") -> Not Registered | F3: =VLOOKUP(A3,Sheet1!A:B,2,FALSE) -> 9323541634 | G3: =_xlfn.IFNA(VLOOKUP(C3,CallLog_Latest!A:H,8,FALSE),"") | H3: =VLOOKUP(C3,[1]Sheet1!$F:$H,3,FALSE) -> F/102 Krishna Residency Behind Sunder Nagar S.V.Road
A4: Jyoti Omprakash Gaggar | B4: Anil Jugalkishor Asawa | C4: 9820265640 | D4: =_xlfn.IFNA(VLOOKUP(C4,CallLog_Latest!A:H,7,FALSE),"Not Called") -> Not Called | E4: =IF(ISNA(VLOOKUP(C4,Registration!A:A,1,FALSE)),"Not Registered","Registered") -> Not Registered | F4: =VLOOKUP(A4,Sheet1!A:B,2,FALSE) -> 9867015031 | G4: =_xlfn.IFNA(VLOOKUP(C4,CallLog_Latest!A:H,8,FALSE),"") | H4: =VLOOKUP(C4,[1]Sheet1!$F:$H,3,FALSE) -> F/102, Krishna Residency, Behind Sunder Nagar, Malad (W
A5: Shri Yogendraji Karwa | B5: Omshankar Harikishan Assawa | C5: 9821460734 | D5: =_xlfn.IFNA(VLOOKUP(C5,CallLog_Latest!A:H,7,FALSE),"Not Called") -> Not Called | E5: =IF(ISNA(VLOOKUP(C5,Registration!A:A,1,FALSE)),"Not Registered","Registered") -> Not Registered | F5: =VLOOKUP(A5,Sheet1!A:B,2,FALSE) -> 9821268271 | G5: =_xlfn.IFNA(VLOOKUP(C5,CallLog_Latest!A:H,8,FALSE),"") | H5: =VLOOKUP(C5,[1]Sheet1!$F:$H,3,FALSE) -> C/403 KINGSTON HEIGHTS Chincholi Bunder Road, Malad (W
A6: Shri Gulabji Jaju | B6: Rahul Omshankar Assawa | C6: 9820454734 | D6: =_xlfn.IFNA(VLOOKUP(C6,CallLog_Latest!A:H,7,FALSE),"Not Called") -> Not Called | E6: =IF(ISNA(VLOOKUP(C6,Registration!A:A,1,FALSE)),"Not Registered","Registered") -> Not Registered | F6: =VLOOKUP(A6,Sheet1!A:B,2,FALSE) -> 9322598681 | G6: =_xlfn.IFNA(VLOOKUP(C6,CallLog_Latest!A:H,8,FALSE),"") | H6: =VLOOKUP(C6,[1]Sheet1!$F:$H,3,FALSE) -> C-403, Kingston Heights Chincholi Bunder Road, Malad (W
A7: Shri Satyaprakashji Malpani | B7: Amitji Rameshwar Bajaj | C7: 9920318503 | D7: =_xlfn.IFNA(VLOOKUP(C7,CallLog_Latest!A:H,7,FALSE),"Not Called") -> Not Called | E7: =IF(ISNA(VLOOKUP(C7,Registration!A:A,1,FALSE)),"Not Registered","Registered") -> Not Registered | F7: =VLOOKUP(A7,Sheet1!A:B,2,FALSE) -> 9969403870 | G7: =_xlfn.IFNA(VLOOKUP(C7,CallLog_Latest!A:H,8,FALSE),"") | H7: =VLOOKUP(C7,[1]Sheet1!$F:$H,3,FALSE) -> G-504 Krishna Residency Atmaram Compound Near Dalmiya College Behind Sunder Nagar Malad (W
A8: Shri Gopalji Gattani | B8: Brijmohan Hardevdas Bajaj | C8: 9322854440 | D8: =_xlfn.IFNA(VLOOKUP(C8,CallLog_Latest!A:H,7,FALSE),"Not Called") -> Not Called | E8: =IF(ISNA(VLOOKUP(C8,Registration!A:A,1,FALSE)),"Not Registered","Registered") -> Not Registered | F8: =VLOOKUP(A8,Sheet1!A:B,2,FALSE) -> 9892726278 | G8: =_xlfn.IFNA(VLOOKUP(C8,CallLog_Latest!A:H,8,FALSE),"") | H8: =VLOOKUP(C8,[1]Sheet1!$F:$H,3,FALSE) -> 209 Malad Shoppint Centre Near Sai Mandir S.V.Road
A9: Shri Sampatkumarji Bhattad | B9: Inderchand Bhavarlal Bajaj | C9: 9892486921 | D9: =_xlfn.IFNA(VLOOKUP(C9,CallLog_Latest!A:H,7,FALSE),"Not Called") -> Not Called | E9: =IF(ISNA(VLOOKUP(C9,Registration!A:A,1,FALSE)),"Not Registered","Registered") -> Not Registered | F9: =VLOOKUP(A9,Sheet1!A:B,2,FALSE) -> 9869798705 | G9: =_xlfn.IFNA(VLOOKUP(C9,CallLog_Latest!A:H,8,FALSE),"") | H9: =VLOOKUP(C9,[1]Sheet1!$F:$H,3,FALSE) -> Sunder Nagar
A10: Shri Anilji Asava | B10: Tarachand Satyanarayan Bajaj | C10: 9869309871 | D10: =_xlfn.IFNA(VLOOKUP(C10,CallLog_Latest!A:H,7,FALSE),"Not Called") -> Not Called | E10: =IF(ISNA(VLOOKUP(C10,Registration!A:A,1,FALSE)),"Not Registered","Registered") -> Not Registered | F10: =VLOOKUP(A10,Sheet1!A:B,2,FALSE) -> 9820265640 | G10: =_xlfn.IFNA(VLOOKUP(C10,CallLog_Latest!A:H,8,FALSE),"") | H10: =VLOOKUP(C10,[1]Sheet1!$F:$H,3,FALSE) -> Flat No.106 The Kanchan Nalanda Chs. Sundar Nagar S.V. Road, Malad (W
A11: Shri Miteshji Tawari | B11: Sureshkumar Shrivallabh Balduva | C11: 9820506066 | D11: =_xlfn.IFNA(VLOOKUP(C11,CallLog_Latest!A:H,7,FALSE),"Not Called") -> Not Called | E11: =IF(ISNA(VLOOKUP(C11,Registration!A:A,1,FALSE)),"Not Registered","Registered") -> Not Registered | F11: =VLOOKUP(A11,Sheet1!A:B,2,FALSE) -> 9820636392 | G11: =_xlfn.IFNA(VLOOKUP(C11,CallLog_Latest!A:H,8,FALSE),"") | H11: =VLOOKUP(C11,[1]Sheet1!$F:$H,3,FALSE) -> B-701, Aruna Residency, Behind Sundar Nagar Opp. Krishna Residency, Nr. Dalmia College, Malad (W
A12: Shri Sureshkumarji Jaju | B12: Rahul Mohandas Bangard | C12: 9820620702 | D12: =_xlfn.IFNA(VLOOKUP(C12,CallLog_Latest!A:H,7,FALSE),"Not Called") -> Not Called | E12: =IF(ISNA(VLOOKUP(C12,Registration!A:A,1,FALSE)),"Not Registered","Registered") -> Not Registered | F12: =VLOOKUP(A12,Sheet1!A:B,2,FALSE) -> 7977439717 | G12: =_xlfn.IFNA(VLOOKUP(C12,CallLog_Latest!A:H,8,FALSE),"") | H12: =VLOOKUP(C12,[1]Sheet1!$F:$H,3,FALSE) -> C-2802 Rustomjee Elanza Off Link Road
A13: Shri Riteshji Chandak | B13: Sachin Narendra Bangur | C13: 8108066289 | D13: =_xlfn.IFNA(VLOOKUP(C13,CallLog_Latest!A:H,7,FALSE),"Not Called") -> Not Called | E13: =IF(ISNA(VLOOKUP(C13,Registration!A:A,1,FALSE)),"Not Registered","Registered") -> Not Registered | F13: =VLOOKUP(A13,Sheet1!A:B,2,FALSE) -> 9967045520 | G13: =_xlfn.IFNA(VLOOKUP(C13,CallLog_Latest!A:H,8,FALSE),"") | H13: =VLOOKUP(C13,[1]Sheet1!$F:$H,3,FALSE) -> G-1106 Palm Court New Link Road
... A967: Shobha Kanhaiyalal Darak | B967: Neelam Gourishankar Toshniwal | C967: 9320770849 | D967: =_xlfn.IFNA(VLOOKUP(C967,CallLog_Latest!A:H,7,FALSE),"Not Called") -> Phone Busy | E967: =IF(ISNA(VLOOKUP(C967,Registration!A:A,1,FALSE)),"Not Registered","Registered") -> Registered | F967: =VLOOKUP(A967,Sheet1!A:B,2,FALSE) -> 9702260383 | G967: =_xlfn.IFNA(VLOOKUP(C967,CallLog_Latest!A:H,8,FALSE),"") -> 0 | H967: =VLOOKUP(C967,[1]Sheet1!$F:$H,3,FALSE) -> Octacrest, 901 -A Wing, Lokhandwala Township, Kandivali (E

Sheet Sheet3
A1: Volunteer Name
A2: Anjali Ishan Mundhra
A3: Shri Harnarayanji Jaju
A4: Shobha Kanhaiyalal Darak
A5: Meenu Lalit Soni
A6: Shri Sampatkumarji Bhattad
A7: Shri Ratishji Mundhra
A8: Shri Purshottamji Kalantri
A9: Shri Vijayji Rathi
A10: Vipin Saboo
A11: Shri Rameshji Mundhra
A12: Shri Nikhilji Chandak
... A28: Jyotsna Sohan Sarda

Sheet Sheet2

Sheet Sheet1
A1: Samit Member Name | B1: Phone
A2: Shri Narayanji Chandak | B2: 9326379737
A3: Shri Manojji Laddha | B3: 9323541634
A4: Jyoti Omprakash Gaggar | B4: 9867015031
A5: Shri Yogendraji Karwa | B5: 9821268271
A6: Shri Gulabji Jaju | B6: 9322598681
A7: Shri Satyaprakashji Malpani | B7: 9969403870
A8: Shri Gopalji Gattani | B8: 9892726278
A9: Shri Sampatkumarji Bhattad | B9: 9869798705
A10: Shri Anilji Asava | B10: 9820265640
A11: Shri Miteshji Tawari | B11: 9820636392
A12: Shri Sureshkumarji Jaju | B12: 7977439717
A13: Shri Riteshji Chandak | B13: 9967045520
... A66: Kavita Sandeep Kabra | B66: 9320624230

Sheet CallLog_Latest
A1: Phone Number Formula | B1: Timestamp | C1: Email Address | D1: Volunteer Name | E1: Person Contacted | F1: Phone Number | G1: Call Status ? | H1: Remarks | I1: Duplicate
A2: =F2 -> 7045887557 | B2: =fromNewLinkREsponses!A114 -> 45668.7 | C2: =fromNewLinkREsponses!B114 -> vipin0785@gmail.com | D2: =fromNewLinkREsponses!D114 -> Vipin Saboo | E2: =fromNewLinkREsponses!E114 -> Rajesh Ramawatar Sodhani | F2: =fromNewLinkREsponses!F114 -> 7045887557 | G2: =fromNewLinkREsponses!C114 -> May be Attending | H2: =fromNewLinkREsponses!G114 -> Not sure. If free 2 would be attending
A3: =F3 -> 7045991852 | B3: 45957.861 | D3: Anjali Ishan Mundhra | E3: Nimish Vijaykumar Bihani | F3: 7045991852 | G3: Maybe Attending 🤔 | I3: =F2=F3 -> FALSE
A4: =F4 -> 7303221249 | B4: =fromNewLinkREsponses!A115 -> 45668.702 | C4: =fromNewLinkREsponses!B115 -> akajainca@gmail.com | D4: =fromNewLinkREsponses!D115 -> Akansha Rahul Somani | E4: =fromNewLinkREsponses!E115 -> Sudha Manoj Falor | F4: =fromNewLinkREsponses!F115 -> 7303221249 | G4: =fromNewLinkREsponses!C115 -> Confirmed Presence | H4: =fromNewLinkREsponses!G115 -> 0 | I4: =F3=F4 -> FALSE
A5: =F5 -> 7387113012 | B5: =fromNewLinkREsponses!A77 -> 45668.661 | C5: =fromNewLinkREsponses!B77 -> caprachirathi@gmail.com | D5: =fromNewLinkREsponses!D77 -> Prachi Ankit Kabra | E5: =fromNewLinkREsponses!E77 -> Rupesh Ramkisan Somani | F5: =fromNewLinkREsponses!F77 -> 7387113012 | G5: =fromNewLinkREsponses!C77 -> Confirmed Presence | H5: =fromNewLinkREsponses!G77 -> He mentioned that it is done ✅ | I5: =F4=F5 -> FALSE
A6: =F6 -> 7506055680 | B6: 45944.771 | D6: Shri Harnarayanji Jaju | E6: Rishbh Rajendrakumar Birla | F6: 7506055680 | G6: Maybe Attending 🤔 | I6: =F5=F6 -> FALSE
A7: =F7 -> 7506371178 | B7: 45957.919 | D7: Shobha Kanhaiyalal Darak | E7: Jyoti Vikas Kasat | F7: 7506371178 | G7: Maybe Attending 🤔 | I7: =F6=F7 -> FALSE
A8: =F8 -> 7506747155 | B8: =fromNewLinkREsponses!A21 -> 45668.574 | C8: =fromNewLinkREsponses!B21 -> jagdish.lahoti92@gmail.com | D8: =fromNewLinkREsponses!D21 -> Jagdish Rameshchand Lahoti | E8: =fromNewLinkREsponses!E21 -> Jayprakash Madanlal Rathi | F8: =fromNewLinkREsponses!F21 -> 7506747155 | G8: =fromNewLinkREsponses!C21 -> Not Reachable | H8: =fromNewLinkREsponses!G21 -> 0 | I8: =F7=F8 -> FALSE
A9: =F9 -> 7506809269 | B9: =fromNewLinkREsponses!A26 -> 45668.577 | C9: =fromNewLinkREsponses!B26 -> jagdish.lahoti92@gmail.com | D9: =fromNewLinkREsponses!D26 -> Jagdish Rameshchand Lahoti | E9: =fromNewLinkREsponses!E26 -> Mehul Dilip Maheshwari | F9: =fromNewLinkREsponses!F26 -> 7506809269 | G9: =fromNewLinkREsponses!C26 -> Confirmed Presence | H9: =fromNewLinkREsponses!G26 -> 0 | I9: =F8=F9 -> FALSE
A10: =F10 -> 7738385694 | B10: =fromNewLinkREsponses!A163 -> 45699.529 | C10: =fromNewLinkREsponses!B163 -> caananddaliya@gmail.com | D10: =fromNewLinkREsponses!D163 -> Anand Omprakash Daliya | E10: =fromNewLinkREsponses!E163 -> Alok Surajmal Mantri | F10: =fromNewLinkREsponses!F163 -> 7738385694 | G10: =fromNewLinkREsponses!C163 -> Not Reachable | H10: =fromNewLinkREsponses!G163 -> Incoming call not active | I10: =F9=F10 -> FALSE
A11: =F11 -> 7738388091 | B11: =fromNewLinkREsponses!A167 -> 45699.537 | C11: =fromNewLinkREsponses!B167 -> caananddaliya@gmail.com | D11: =fromNewLinkREsponses!D167 -> Anand Omprakash Daliya | E11: =fromNewLinkREsponses!E167 -> Alok Purshottamlal Bang | F11: =fromNewLinkREsponses!F167 -> 7738388091 | G11: =fromNewLinkREsponses!C167 -> May be Attending | H11: =fromNewLinkREsponses!G167 -> Will confirm soon | I11: =F10=F11 -> FALSE
A12: =F12 -> 7798729876 | B12: =fromNewLinkREsponses!A173 -> 45699.585 | C12: =fromNewLinkREsponses!B173 -> prdhoot@gmail.com | D12: =fromNewLinkREsponses!D173 -> Prateek Ramesh Dhoot | E12: =fromNewLinkREsponses!E173 -> Amit Omprakash Bahedia | F12: =fromNewLinkREsponses!F173 -> 7798729876 | G12: =fromNewLinkREsponses!C173 -> Not Reachable | H12: =fromNewLinkREsponses!G173 -> phone is with some other person | I12: =F11=F12 -> FALSE
A13: =F13 -> 7874999912 | B13: 45957.863 | D13: Anjali Ishan Mundhra | E13: Nirmal Manishankar Maroo | F13: 7874999912 | G13: Confirmed Presence ✅ | I13: =F12=F13 -> FALSE
A14: =F14 -> 7977214168 | B14: 45943.492 | D14: Meenu Lalit Soni | E14: Kala Jaygopal Kasat | F14: 7977214168 | G14: Confirmed Presence ✅ | I14: =F13=F14 -> FALSE
A15: =F15 -> 7977439717 | B15: =fromNewLinkREsponses!A75 -> 45668.654 | C15: =fromNewLinkREsponses!B75 -> arkmantri@gmail.com | D15: =fromNewLinkREsponses!D75 -> Shri Avinash Mantri | E15: =fromNewLinkREsponses!E75 -> Sureshkumar Ramniwas Jajoo | F15: =fromNewLinkREsponses!F75 -> 7977439717 | G15: =fromNewLinkREsponses!C75 -> Confirmed Presence | H15: =fromNewLinkREsponses!G75 -> Will register | I15: =F14=F15 -> FALSE
A16: =F16 -> 8097078048 | B16: 45957.924 | D16: Shobha Kanhaiyalal Darak | E16: Ranu Arun Kabra | F16: 8097078048 | G16: Maybe Attending 🤔 | I16: =F15=F16 -> FALSE
A17: =F17 -> 8291612305 | B17: =fromNewLinkREsponses!A144 -> 45699.438 | C17: =fromNewLinkREsponses!B144 -> onlinevdarak@gmail.com | D17: =fromNewLinkREsponses!D144 -> Varun Kanhaiyalal Darak | E17: =fromNewLinkREsponses!E144 -> Shubham Sampat Bhattad | F17: =fromNewLinkREsponses!F144 -> 8291612305 | G17: =fromNewLinkREsponses!C144 -> Phone Busy | H17: =fromNewLinkREsponses!G144 -> 0 | I17: =F16=F17 -> FALSE
A18: =F18 -> 8425048184 | B18: =fromNewLinkREsponses!A172 -> 45699.584 | C18: =fromNewLinkREsponses!B172 -> prdhoot@gmail.com | D18: =fromNewLinkREsponses!D172 -> Prateek Ramesh Dhoot | E18: =fromNewLinkREsponses!E172 -> Akhilesh Premkishan Mantri | F18: =fromNewLinkREsponses!F172 -> 8425048184 | G18: =fromNewLinkREsponses!C172 -> Confirmed Presence | H18: =fromNewLinkREsponses!G172 -> said will register | I18: =F17=F18 -> FALSE
A19: =F19 -> 8446381106 | B19: 45957.909 | D19: Shobha Kanhaiyalal Darak | E19: Bhagyashree Akshay Rathi | F19: 8446381106 | G19: Maybe Attending 🤔 | I19: =F18=F19 -> FALSE
A20: =F20 -> 8600106060 | B20: 45942.663 | D20: Shri Sampatkumarji Bhattad | E20: Pushpak Manoj Laddha | F20: 8600106060 | G20: Confirmed Presence ✅ | I20: =F19=F20 -> FALSE
A21: =F21 -> 8652071304 | B21: 45957.904 | D21: Shobha Kanhaiyalal Darak | E21: Abha Damodar Karwa | F21: 8652071304 | G21: Not Reachable | I21: =F20=F21 -> FALSE
A22: =F22 -> 8777740593 | B22: =fromNewLinkREsponses!A20 -> 45668.573 | C22: =fromNewLinkREsponses!B20 -> jagdish.lahoti92@gmail.com | D22: =fromNewLinkREsponses!D20 -> Jagdish Rameshchand Lahoti | E22: =fromNewLinkREsponses!E20 -> Harinarayan Champalal Karnani | F22: =fromNewLinkREsponses!F20 -> 8777740593 | G22: =fromNewLinkREsponses!C20 -> Not Reachable | H22: =fromNewLinkREsponses!G20 -> 0 | I22: =F21=F22 -> FALSE
A23: =F23 -> 8779689904 | B23: =fromNewLinkREsponses!A145 -> 45699.439 | C23: =fromNewLinkREsponses!B145 -> rassawa@gmail.com | D23: =fromNewLinkREsponses!D145 -> Rahul Omshankar Assawa | E23: =fromNewLinkREsponses!E145 -> Preet Premswaroop Sikchi | F23: =fromNewLinkREsponses!F145 -> 8779689904 | G23: =fromNewLinkREsponses!C145 -> Not Reachable | H23: =fromNewLinkREsponses!G145 -> Number not available | I23: =F22=F23 -> FALSE
A24: =F24 -> 8779756681 | B24: =fromNewLinkREsponses!A30 -> 45668.579 | C24: =fromNewLinkREsponses!B30 -> jagdish.lahoti92@gmail.com | D24: =fromNewLinkREsponses!D30 -> Jagdish Rameshchand Lahoti | E24: =fromNewLinkREsponses!E30 -> Murlimanohar Bodulaal Kasat | F24: =fromNewLinkREsponses!F30 -> 8779756681 | G24: =fromNewLinkREsponses!C30 -> Not Reachable | H24: =fromNewLinkREsponses!G30 -> 0 | I24: =F23=F24 -> FALSE
A25: =F25 -> 8823915926 | B25: =fromNewLinkREsponses!A146 -> 45699.44 | C25: =fromNewLinkREsponses!B146 -> onlinevdarak@gmail.com | D25: =fromNewLinkREsponses!D146 -> Varun Kanhaiyalal Darak | E25: =fromNewLinkREsponses!E146 -> Siddhant Kishan Ladda | F25: =fromNewLinkREsponses!F146 -> 8823915926 | G25: =fromNewLinkREsponses!C146 -> Not Reachable | H25: =fromNewLinkREsponses!G146 -> Number does not exist. Needs correction/revision in calling list | I25: =F24=F25 -> FALSE
A26: =F26 -> 8871984007 | B26: =fromNewLinkREsponses!A169 -> 45699.539 | C26: =fromNewLinkREsponses!B169 -> swatichandak90@gmail.com | D26: =fromNewLinkREsponses!D169 -> Kaushalyadevi Dineshkumar Gaggad | E26: =fromNewLinkREsponses!E169 -> Prachi Ankit Kabra | F26: =fromNewLinkREsponses!F169 -> 8871984007 | G26: =fromNewLinkREsponses!C169 -> Confirmed Presence | H26: =fromNewLinkREsponses!G169 -> 0 | I26: =F25=F26 -> FALSE
A27: =F27 -> 8879097778 | B27: =fromNewLinkREsponses!A149 -> 45699.441 | C27: =fromNewLinkREsponses!B149 -> rassawa@gmail.com | D27: =fromNewLinkREsponses!D149 -> Rahul Omshankar Assawa | E27: =fromNewLinkREsponses!E149 -> Radheyshyam Bankatlal Soni | F27: =fromNewLinkREsponses!F149 -> 8879097778 | G27: =fromNewLinkREsponses!C149 -> Phone Busy | H27: =fromNewLinkREsponses!G149 -> Will try again | I27: =F26=F27 -> FALSE
A28: =F28 -> 8879380701 | B28: 45957.861 | D28: Anjali Ishan Mundhra | E28: Niranjan Omprakash Mundra | F28: 8879380701 | G28: Confirmed Presence ✅ | I28: =F27=F28 -> FALSE
A29: =F29 -> 8919841473 | B29: =fromNewLinkREsponses!A130 -> 45699.422 | C29: =fromNewLinkREsponses!B130 -> onlinevdarak@gmail.com | D29: =fromNewLinkREsponses!D130 -> Varun Kanhaiyalal Darak | E29: =fromNewLinkREsponses!E130 -> Ashish DIneshchandra Baheti | F29: =fromNewLinkREsponses!F130 -> 8919841473 | G29: =fromNewLinkREsponses!C130 -> Not Coming | H29: =fromNewLinkREsponses!G130 -> Have a family function on same day | I29: =F28=F29 -> FALSE
A30: =F30 -> 8999747002 | B30: =fromNewLinkREsponses!A119 -> 45668.767 | C30: =fromNewLinkREsponses!B119 -> jyotis1311@gmail.com | D30: =fromNewLinkREsponses!D119 -> Jyotsna Sohan Sarda | E30: =fromNewLinkREsponses!E119 -> Kanchan Atul Bhutada | F30: =fromNewLinkREsponses!F119 -> 8999747002 | G30: =fromNewLinkREsponses!C119 -> Confirmed Presence | H30: =fromNewLinkREsponses!G119 -> Coming | I30: =F29=F30 -> FALSE
A31: =F31 -> 9000438763 | B31: 45943.492 | D31: Meenu Lalit Soni | E31: Archana Prakash Rathi | F31: 9000438763 | G31: Not Reachable | H31: Wrong no | I31: =F30=F31 -> FALSE
A32: =F32 -> 9004255553 | B32: 45941.613 | D32: Shri Ratishji Mundhra | E32: Jugalkishor Damodardas Kela | F32: 9004255553 | G32: Confirmed Presence ✅ | I32: =F31=F32 -> FALSE
A33: =F33 -> 9004259412 | B33: 45942.449 | D33: Shri Purshottamji Kalantri | E33: Piyush Ramesh Gattani | F33: 9004259412 | G33: Confirmed Presence ✅ | I33: =F32=F33 -> FALSE
A34: =F34 -> 9004351568 | B34: 45943.52 | D34: Shri Harnarayanji Jaju | E34: Abhinav Narendrakumar Maheshwari | F34: 9004351568 | G34: Confirmed Presence ✅ | I34: =F33=F34 -> FALSE
A35: =F35 -> 9004481082 | B35: =fromNewLinkREsponses!A40 -> 45668.583 | C35: =fromNewLinkREsponses!B40 -> impt85@gmail.com | D35: =fromNewLinkREsponses!D40 -> Shri Premji Taparia | E35: =fromNewLinkREsponses!E40 -> Ramanuj Babulal Dad | F35: =fromNewLinkREsponses!F40 -> 9004481082 | G35: =fromNewLinkREsponses!C40 -> Confirmed Presence | H35: =fromNewLinkREsponses!G40 -> 0 | I35: =F34=F35 -> FALSE
A36: =F36 -> 9004547878 | B36: 45958.875 | D36: Shri Vijayji Rathi | E36: Pannechand Fatehchand Sarda | F36: 9004547878 | G36: Confirmed Presence ✅ | H36: 3 member | I36: =F35=F36 -> FALSE
A37: =F37 -> 9004677979 | B37: 45959.382 | D37: Vipin Saboo | E37: Animesh Mahendrakumar Saboo | F37: 9004677979 | G37: Maybe Attending 🤔 | H37: 2 people may attend | I37: =F36=F37 -> FALSE
A38: =F38 -> 9022963335 | B38: 45949.477 | D38: Shri Rameshji Mundhra | E38: Amith Bhagwandas Bharadiya | F38: 9022963335 | G38: Phone Busy | H38: Didn’t pickup | I38: =F37=F38 -> FALSE
A39: =F39 -> 9028711211 | B39: 45942.648 | D39: Shri Sampatkumarji Bhattad | E39: Abhishek Radheshyam Jaju | F39: 9028711211 | G39: Confirmed Presence ✅ | I39: =F38=F39 -> FALSE
A40: =F40 -> 9029355691 | B40: 45957.858 | D40: Anjali Ishan Mundhra | E40: Dhruv Vrijesh Kabra | F40: 9029355691 | G40: Not Coming 🚫 | H40: Exams going on | I40: =F39=F40 -> FALSE
...

Sheet fromNewLinkREsponses
A1: Timestamp | B1: Email address | C1: Call Status ? | D1: Volunteer Name | E1: Person Contacted | F1: Phone Number | G1: Remarks
A2: 31/10/2025 11:45:03 | B2: ratishmoondra@gmail.com | C2: Not Reachable | D2: Shri Ratishji Mundhra | E2: Alekh Jaggannath Gandhi | F2: 9769422928 | G2: Not on whatsapp
A3: 31/10/2025 11:49:22 | B3: ratishmoondra2025@gmail.com | C3: Phone Busy | D3: Rahul Omshankar Assawa | E3: Ashok Harnarain Chandak | F3: 9819920011
A4: 31/10/2025 11:53:47 | B4: ratishmoondra@gmail.com | C4: Not Reachable | D4: Shri Ratishji Mundhra | E4: Sureshkumar Girdharilal Sarda | F4: 9322874559
A5: 31/10/2025 21:44:16 | B5: nikechandak@gmail.com | C5: Confirmed Presence | D5: Shri Nikhilji Chandak | E5: Rajkumar Shyamsunder Saboo | F5: 9324811111 | G5: 2 member ll join
A6: 31/10/2025 21:51:19 | B6: nikechandak@gmail.com | C6: Confirmed Presence | D6: Shri Nikhilji Chandak | E6: Saurabh Harshvardhan Lakhotiya | F6: 9820524522
A7: 31/10/2025 21:53:46 | B7: nikechandak@gmail.com | C7: Confirmed Presence | D7: Shri Nikhilji Chandak | E7: Shyamsunder Thakurdas Laddha | F7: 9833345544 | G7: 3 member ll join
A8: 31/10/2025 21:56:58 | B8: nikechandak@gmail.com | C8: Not Reachable | D8: Shri Nikhilji Chandak | E8: Sunilkumar Ganeshilal Bharadia | F8: 9928444867 | G8: No is not taking incoming calls
A9: 31/10/2025 21:57:30 | B9: nikechandak@gmail.com | C9: Confirmed Presence | D9: Shri Nikhilji Chandak | E9: Subhash Loonkaran Gandhi | F9: 9819578232 | G9: 3 member ll join
A10: 31/10/2025 22:02:07 | B10: nikechandak@gmail.com | C10: Confirmed Presence | D10: Shri Nikhilji Chandak | E10: Vinit Rameshchandra Maheshwari | F10: 9320308008 | G10: 3 people have confirmed
A11: 31/10/2025 22:02:55 | B11: nikechandak@gmail.com | C11: Confirmed Presence | D11: Shri Nikhilji Chandak | E11: Unmesh Shrikant Bhandari | F11: 9324285448
A12: 31/10/2025 22:08:42 | B12: nikechandak@gmail.com | C12: Confirmed Presence | D12: Shri Nikhilji Chandak | E12: Anil Shantilal Nawal | F12: 9821692529 | G12: 4 people have confirmed
A13: 31/10/2025 22:10:15 | B13: nikechandak@gmail.com | C13: Not Coming | D13: Shri Nikhilji Chandak | E13: Bhupendra Ghanshyandas Rathi | F13: 9867122626
A14: 31/10/2025 22:18:00 | B14: nikechandak@gmail.com | C14: Not Reachable | D14: Shri Nikhilji Chandak | E14: Satish Labhchand Totla | F14: 9323930259
A15: 45668.355 | B15: kkankkbr2025@gmail.com | C15: Not Coming | D15: Ankit Sureshchandra Kabra | E15: Jitendra Kamalkishor Gandhi | F15: 9867319071 | G15: Wrong number
A16: 45668.482 | B16: ravibhattad@gmail.com | C16: Confirmed Presence | D16: Ravindra Bhattad | E16: Hemantkumar Shyamsundar Bahedia | F16: 9702224535 | G16: Already Registered
A17: 45668.484 | B17: onlinevdarak@gmail.com | C17: Not Coming | D17: Varun Kanhaiyalal Darak | E17: Anand Gulabchand Mantri | F17: 9819461122 | G17: Not in town
A18: 45668.571 | B18: jagdish.lahoti92@gmail.com | C18: Confirmed Presence | D18: Jagdish Rameshchand Lahoti | E18: Dilip Balkrishna Mandhana | F18: 9930723354
A19: 45668.572 | B19: jagdish.lahoti92@gmail.com | C19: Confirmed Presence | D19: Jagdish Rameshchand Lahoti | E19: Gajanand Ganpatrai Gaggar | F19: 9320969649
A20: 45668.573 | B20: jagdish.lahoti92@gmail.com | C20: Not Reachable | D20: Jagdish Rameshchand Lahoti | E20: Harinarayan Champalal Karnani | F20: 8777740593
A21: 45668.574 | B21: jagdish.lahoti92@gmail.com | C21: Not Reachable | D21: Jagdish Rameshchand Lahoti | E21: Jayprakash Madanlal Rathi | F21: 7506747155
A22: 45668.575 | B22: jagdish.lahoti92@gmail.com | C22: Confirmed Presence | D22: Jagdish Rameshchand Lahoti | E22: Kamal Bhawarniwas Rathi | F22: 9702292855
A23: 45668.575 | B23: jagdish.lahoti92@gmail.com | C23: Not Reachable | D23: Jagdish Rameshchand Lahoti | E23: Lalit Sitaram Kabra | F23: 9820659788
A24: 45668.576 | B24: jagdish.lahoti92@gmail.com | C24: Confirmed Presence | D24: Jagdish Rameshchand Lahoti | E24: Madhusudan Narayanlal Sarda | F24: 9322397174
A25: 45668.576 | B25: impt85@gmail.com | C25: Confirmed Presence | D25: Shri Premji Taparia | E25: Abhishek Nandkishor Rathi | F25: 9820804282
A26: 45668.577 | B26: jagdish.lahoti92@gmail.com | C26: Confirmed Presence | D26: Jagdish Rameshchand Lahoti | E26: Mehul Dilip Maheshwari | F26: 7506809269
A27: 45668.577 | B27: impt85@gmail.com | C27: Confirmed Presence | D27: Shri Premji Taparia | E27: Akshay Sunil Rathi | F27: 9769373893
A28: 45668.579 | B28: arkmantri@gmail.com | C28: Not Reachable | D28: Shri Avinash Mantri | E28: Malay Laxminarayan Bhattar | F28: 9833933540 | G28: Number doesn't exist
A29: 45668.579 | B29: impt85@gmail.com | C29: Confirmed Presence | D29: Shri Premji Taparia | E29: Ganeshilal Ramkishan Bharadia | F29: 9819789523
A30: 45668.579 | B30: jagdish.lahoti92@gmail.com | C30: Not Reachable | D30: Jagdish Rameshchand Lahoti | E30: Murlimanohar Bodulaal Kasat | F30: 8779756681
A31: 45668.58 | B31: jagdish.lahoti92@gmail.com | C31: Not Reachable | D31: Jagdish Rameshchand Lahoti | E31: Prakash Ramvilas Hurkat | F31: 9820230357
A32: 45668.581 | B32: impt85@gmail.com | C32: Confirmed Presence | D32: Shri Premji Taparia | E32: Gopalkishan Madanlalji Toshniwal | F32: 9821070860
A33: 45668.581 | B33: impt85@gmail.com | C33: Not Reachable | D33: Shri Premji Taparia | E33: Kamalkishore Lunkaran Gandhi | F33: 9892879893
A34: 45668.582 | B34: jagdish.lahoti92@gmail.com | C34: Confirmed Presence | D34: Jagdish Rameshchand Lahoti | E34: Raj Tolaram Lahoti | F34: 9867328282
A35: 45668.582 | B35: impt85@gmail.com | C35: Not Reachable | D35: Shri Premji Taparia | E35: Narendra Shyamsundar Laddha | F35: 9820798553
A36: 45668.582 | B36: arkmantri@gmail.com | C36: May be Attending | D36: Shri Avinash Mantri | E36: Ashish Gopallal Pugalia | F36: 9820444531 | G36: Will let us know
A37: 45668.582 | B37: impt85@gmail.com | C37: Phone Busy | D37: Shri Premji Taparia | E37: Arun Shivkumar Saboo | F37: 9322275160
A38: 45668.582 | B38: jagdish.lahoti92@gmail.com | C38: Confirmed Presence | D38: Jagdish Rameshchand Lahoti | E38: Rajesh Purushottam Bang | F38: 9820066427
A39: 45668.583 | B39: jagdish.lahoti92@gmail.com | C39: Not Coming | D39: Jagdish Rameshchand Lahoti | E39: Ramanuj Ramakishan Soni | F39: 9324051973
A40: 45668.583 | B40: impt85@gmail.com | C40: Confirmed Presence | D40: Shri Premji Taparia | E40: Ramanuj Babulal Dad | F40: 9004481082
...

Sheet Registration
A1: Mobile Number | B1: # OF People | C1: Mob | D1: Name | F1: Timestamp | G1: Email Address | H1: 👥 How many members from your family will be attending? 🎉 (Including yourself!) आपके परिवार से कितने सदस्य उपस्थित रहेंगे? (स्वयं को मिलाकर!) | I1: 📱 WhatsApp Number 📞 | J1: 📝 Your Name | K1: 📍 Your Location🌍 | L1: UPI Transaction ID (Last 5 Digits please) | M1: Column 7 | N1: Registration ID
A2: =C2 -> 9993325021 | B2: =H2 -> 2 | C2: =I2 -> 9993325021 | D2: =J2 -> Ronak karwa | E2: =VLOOKUP(A2,DataPublished!C:C,1,FALSE) -> 9993325021 | F2: 45939.432 | G2: ronakkarwa@gmail.com | H2: 2 | I2: 9993325021 | J2: Ronak karwa | K2: Kandivali - Malad Area | L2: 528265775027 | N2: REG-2025-00115
A3: =C3 -> 9833705425 | B3: =H3 -> 4 | C3: =I3 -> 9833705425 | D3: =J3 -> Ramesh Mundhra | E3: =VLOOKUP(A3,DataPublished!C:C,1,FALSE) -> 9833705425 | F3: 45941.588 | G3: rameshmundhra123@gmail.com | H3: 4 | I3: 9833705425 | J3: Ramesh Mundhra | K3: Kandivali - Malad Area | L3: 112486806258 | N3: REG-2025-00116
A4: =C4 -> 9820522401 | B4: =H4 -> 5 | C4: =I4 -> 9820522401 | D4: =J4 -> Radheshyam Lahoti | E4: =VLOOKUP(A4,DataPublished!C:C,1,FALSE) -> 9820522401 | F4: 45944.771 | G4: rslahoti1@gmail.com | H4: 5 | I4: 9820522401 | J4: Radheshyam Lahoti | K4: Kandivali - Malad Area | L4: 54634 | N4: REG-2025-00117
A5: =C5 -> 9987207838 | B5: =H5 -> 2 | C5: =I5 -> 9987207838 | D5: =J5 -> Sarla Toshniwal | E5: =VLOOKUP(A5,DataPublished!C:C,1,FALSE) -> #N/A | F5: 45948.644 | G5: sarlatoshniwal63@gmail.com | H5: 2 | I5: 9987207838 | J5: Sarla Toshniwal | K5: Kandivali - Malad Area | L5: 81820 | N5: REG-2025-00118
A6: =C6 -> 9867711122 | B6: =H6 -> 3 | C6: =I6 -> 9867711122 | D6: =J6 -> Ravi Soni | E6: =VLOOKUP(A6,DataPublished!C:C,1,FALSE) -> 9867711122 | F6: 45949.444 | G6: dbaocr@gmail.com | H6: 3 | I6: 9867711122 | J6: Ravi Soni | K6: Kandivali - Malad Area | L6: 81103 | N6: REG-2025-00119
A7: =C7 -> 9920307573 | B7: =H7 -> 4 | C7: =I7 -> 9920307573 | D7: =J7 -> Mayur Dilip Biyani | E7: =VLOOKUP(A7,DataPublished!C:C,1,FALSE) -> 9920307573 | F7: 45951.821 | G7: mayurbiyani2003@gmail.com | H7: 4 | I7: 9920307573 | J7: Mayur Dilip Biyani | K7: Kandivali - Malad Area | L7: 1991 | N7: REG-2025-00120
A8: =C8 -> 9322206108 | B8: =H8 -> 5 | C8: =I8 -> 9322206108 | D8: =J8 -> Purushottam Kalantri | E8: =VLOOKUP(A8,DataPublished!C:C,1,FALSE) -> 9322206108 | F8: 45957.75 | G8: umeshkalantri@gmail.com | H8: 5 | I8: 9322206108 | J8: Purushottam Kalantri | K8: Kandivali - Malad Area | L8: 6381 | N8: REG-2025-00121
A9: =C9 -> 9004928430 | B9: =H9 -> 1 | C9: =I9 -> 9004928430 | D9: =J9 -> Naresh Dhoot | E9: =VLOOKUP(A9,DataPublished!C:C,1,FALSE) -> 9004928430 | F9: 45957.952 | G9: meghmasti@gmail.com | H9: 1 | I9: 9004928430 | J9: Naresh Dhoot | K9: Kandivali - Malad Area | L9: 77239 | N9: REG-2025-00122
A10: =C10 -> 9967031830 | B10: =H10 -> 3 | C10: =I10 -> 9967031830 | D10: =J10 -> Rinku Rajgopal Kabra | E10: =VLOOKUP(A10,DataPublished!C:C,1,FALSE) -> 9967031830 | F10: 45958.401 | G10: rinkukabra74@gmail.com | H10: 3 | I10: 9967031830 | J10: Rinku Rajgopal Kabra | K10: Kandivali - Malad Area | L10: 93461 | N10: REG-2025-00123
A11: =C11 -> 9820001618 | B11: =H11 -> 8 | C11: =I11 -> 9820001618 | D11: =J11 -> Ramavtar Gaggar | E11: =VLOOKUP(A11,DataPublished!C:C,1,FALSE) -> 9820001618 | F11: 45958.442 | G11: ram.gaggar@gmail.com | H11: 8 | I11: 9820001618 | J11: Ramavtar Gaggar | K11: Kandivali - Malad Area | L11: 8791 | N11: REG-2025-00124
A12: =C12 -> 9975708960 | B12: =H12 -> 3 | C12: =I12 -> 9975708960 | D12: =J12 -> Priyanka singhi | E12: =VLOOKUP(A12,DataPublished!C:C,1,FALSE) -> #N/A | F12: 45958.465 | G12: priyankapkakani@gmail.com | H12: 3 | I12: 9975708960 | J12: Priyanka singhi | K12: Kandivali - Malad Area | L12: 80153 | N12: REG-2025-00125
A13: =C13 -> 9964005943 | B13: =H13 -> 2 | C13: =I13 -> 9964005943 | D13: =J13 -> Rohit Zanwar | E13: =VLOOKUP(A13,DataPublished!C:C,1,FALSE) -> 9964005943 | F13: 45958.682 | G13: rzanwar103@gmail.com | H13: 2 | I13: 9964005943 | J13: Rohit Zanwar | K13: Kandivali - Malad Area | L13: 71985 | N13: REG-2025-00126
... A20: =C20 -> 9833922453 | B20: =H20 -> 6 | C20: =I20 -> 9833922453 | D20: =J20 -> Pallavi Kasat | E20: =VLOOKUP(A20,DataPublished!C:C,1,FALSE) -> #N/A | F20: 45959.375 | G20: cheerspallavi@gmail.com | H20: 6 | I20: 9833922453 | J20: Pallavi Kasat | K20: Kandivali - Malad Area | L20: 16427 | N20: REG-2025-00133
A21: =C21 -> 9002826174 | B21: =H21 -> 2 | C21: =I21 -> 9002826174 | D21: =J21 -> Nidhi taparia | E21: =VLOOKUP(A21,DataPublished!C:C,1,FALSE) -> #N/A | F21: 31/10/2025 11:07:53 | G21: ronak.karwa@lendenclub.com | H21: 2 | I21: 9002826174 | J21: Nidhi taparia | K21: Kandivali - Malad Area | L21: 16878
A22: =C22 -> 9819146316 | B22: =H22 -> 4 | C22: =I22 -> 9819146316 | D22: =J22 -> Vishnu Toshniwal | E22: =VLOOKUP(A22,DataPublished!C:C,1,FALSE) -> 9819146316 | F22: 31/10/2025 11:24:48 | G22: toshniwalvishnu8@gmail.com | H22: 4 | I22: 9819146316 | J22: Vishnu Toshniwal | K22: Kandivali - Malad Area | L22: 69118
A23: =C23 -> 7506460775 | B23: =H23 -> 2 | C23: =I23 -> 7506460775 | D23: =J23 -> Raunak Rathi | E23: =VLOOKUP(A23,DataPublished!C:C,1,FALSE) -> #N/A | F23: 31/10/2025 12:35:57 | G23: raunakrathi20@gmail.com | H23: 2 | I23: 7506460775 | J23: Raunak Rathi | K23: Kandivali - Malad Area | L23: 40851
A24: =C24 -> 9920485387 | B24: =H24 -> 3 | C24: =I24 -> 9920485387 | D24: =J24 -> Dinesh Hari Kabra | E24: =VLOOKUP(A24,DataPublished!C:C,1,FALSE) -> 9920485387 | F24: 31/10/2025 12:46:30 | G24: dineshkabra200@gmail.com | H24: 3 | I24: 9920485387 | J24: Dinesh Hari Kabra | K24: Kandivali - Malad Area | L24: 42270
A25: =C25 -> 9820747070 | B25: =H25 -> 3 | C25: =I25 -> 9820747070 | D25: =J25 -> Santosh Dhoot | E25: =VLOOKUP(A25,DataPublished!C:C,1,FALSE) -> 9820747070 | F25: 31/10/2025 17:18:24 | G25: dhootkhush@gmail.com | H25: 3 | I25: 9820747070 | J25: Santosh Dhoot | K25: Kandivali - Malad Area | L25: 72805
A26: =C26 -> 7387113012 | B26: =H26 -> 2 | C26: =I26 -> 7387113012 | D26: =J26 -> Rupesh Somani | E26: =VLOOKUP(A26,DataPublished!C:C,1,FALSE) -> 7387113012 | F26: 31/10/2025 17:33:46 | G26: rupesh.mailbox@gmail.com | H26: 2 | I26: 7387113012 | J26: Rupesh Somani | K26: Kandivali - Malad Area | L26: 70086
A27: =C27 -> 9987715825 | B27: =H27 -> 4 | C27: =I27 -> 9987715825 | D27: =J27 -> Yash Malani | E27: =VLOOKUP(A27,DataPublished!C:C,1,FALSE) -> #N/A | F27: 31/10/2025 17:39:44 | G27: malaniyash2806@gmail.com | H27: 4 | I27: 9987715825 | J27: Yash Malani | K27: Kandivali - Malad Area | L27: 10477
A28: =C28 -> 9323192651 | B28: =H28 -> 1 | C28: =I28 -> 9323192651 | D28: =J28 -> Nilesh Tawari | E28: =VLOOKUP(A28,DataPublished!C:C,1,FALSE) -> 9323192651 | F28: 31/10/2025 20:26:47 | G28: tawari.nilesh2@gmail.com | H28: 1 | I28: 9323192651 | J28: Nilesh Tawari | K28: Kandivali - Malad Area | L28: 15925
A29: =C29 -> 9529611813 | B29: =H29 -> 4 | C29: =I29 -> 9529611813 | D29: =J29 -> Abhishek Rathi | E29: =VLOOKUP(A29,DataPublished!C:C,1,FALSE) -> 9529611813 | F29: 31/10/2025 22:34:32 | G29: caabhishekrathi19@gmail.com | H29: 4 | I29: 9529611813 | J29: Abhishek Rathi | K29: Kandivali - Malad Area | L29: 90705
A30: =C30 -> 9833451953 | B30: =H30 -> 6 | C30: =I30 -> 9833451953 | D30: =J30 -> Khushbu bhala | E30: =VLOOKUP(A30,DataPublished!C:C,1,FALSE) -> #N/A | F30: 31/10/2025 22:38:58 | G30: khushbu.malpani@gmail.com | H30: 6 | I30: 9833451953 | J30: Khushbu bhala | K30: Kandivali - Malad Area | L30: 97389
A31: =C31 -> 9004481082 | B31: =H31 -> 3 | C31: =I31 -> 9004481082 | D31: =J31 -> Ramanuj Dad | E31: =VLOOKUP(A31,DataPublished!C:C,1,FALSE) -> 9004481082 | F31: 31/10/2025 23:23:58 | G31: ramanuj.in@gmail.com | H31: 3 | I31: 9004481082 | J31: Ramanuj Dad | K31: Kandivali - Malad Area | L31: 19968
A32: =C32 -> 8383088008 | B32: =H32 -> 3 | C32: =I32 -> 8383088008 | D32: =J32 -> Sanwariya Somani | E32: =VLOOKUP(A32,DataPublished!C:C,1,FALSE) -> 8383088008 | F32: 45668.404 | G32: casanwariya@gmail.com | H32: 3 | I32: 8383088008 | J32: Sanwariya Somani | K32: Kandivali - Malad Area | L32: 36151
A33: =C33 -> 9867621977 | B33: =H33 -> 2 | C33: =I33 -> 9867621977 | D33: =J33 -> Naresh Kabra | E33: =VLOOKUP(A33,DataPublished!C:C,1,FALSE) -> 9867621977 | F33: 45668.447 | G33: rtrnavneetkabra@gmail.com | H33: 2 | I33: 9867621977 | J33: Naresh Kabra | K33: Kandivali - Malad Area | L33: 90139
A34: =C34 -> 9819364345 | B34: =H34 -> 4 | C34: =I34 -> 9819364345 | D34: =J34 -> Ankit Kabra | E34: =VLOOKUP(A34,DataPublished!C:C,1,FALSE) -> 9819364345 | F34: 45668.471 | G34: kkankkbr2025@gmail.com | H34: 4 | I34: 9819364345 | J34: Ankit Kabra | K34: Kandivali - Malad Area | L34: 10651
A35: =C35 -> 9920020171 | B35: =H35 -> 4 | C35: =I35 -> 9920020171 | D35: =J35 -> Harish Bhootra | E35: =VLOOKUP(A35,DataPublished!C:C,1,FALSE) -> #N/A | F35: 45668.534 | G35: haribhootra@gmail.com | H35: 4 | I35: 9920020171 | J35: Harish Bhootra | K35: Other | L35: 64713
A36: =C36 -> 9664467750 | B36: =H36 -> 2 | C36: =I36 -> 9664467750 | D36: =J36 -> Shivratan gaggar | E36: =VLOOKUP(A36,DataPublished!C:C,1,FALSE) -> 9664467750 | F36: 45668.55 | G36: gaggarsratan@gmail.com | H36: 2 | I36: 9664467750 | J36: Shivratan gaggar | K36: Kandivali - Malad Area | L36: 46959
A37: =C37 -> 9320770849 | B37: =H37 -> 2 | C37: =I37 -> 9320770849 | D37: =J37 -> Neelam Toshniwal | E37: =VLOOKUP(A37,DataPublished!C:C,1,FALSE) -> 9320770849 | F37: 45668.56 | G37: neelam.toshniwal@gmail.com | H37: 2 | I37: 9320770849 | J37: Neelam Toshniwal | K37: Kandivali - Malad Area | L37: 72503
A38: =C38 -> 9869834085 | B38: =H38 -> 2 | C38: =I38 -> 9869834085 | D38: =J38 -> Sumit Somani | E38: =VLOOKUP(A38,DataPublished!C:C,1,FALSE) -> #N/A | F38: 45668.6 | G38: sumitssomani@gmail.com | H38: 2 | I38: 9869834085 | J38: Sumit Somani | K38: Kandivali - Malad Area | L38: 41509
A39: =C39 -> 7506747155 | B39: =H39 -> 4 | C39: =I39 -> 7506747155 | D39: =J39 -> Jai Prakash Rathi | E39: =VLOOKUP(A39,DataPublished!C:C,1,FALSE) -> 7506747155 | F39: 45668.616 | G39: rathijp56@gmail.com | H39: 4 | I39: 7506747155 | J39: Jai Prakash Rathi | K39: Kandivali - Malad Area | L39: 33904
A40: =C40 -> 9967841114 | B40: =H40 -> 3 | C40: =I40 -> 9967841114 | D40: =J40 -> Ramesh Mundra | E40: =VLOOKUP(A40,DataPublished!C:C,1,FALSE) -> 9967841114 | F40: 45668.69 | G40: ramesh.mundra1@gmail.com | H40: 3 | I40: 9967841114 | J40: Ramesh Mundra | K40: Kandivali - Malad Area | L40: 17693
A41: =C41 -> 9322853147 | B41: =H41 -> 2 | C41: =I41 -> 9322853147 | D41: =J41 -> Nandkishore Attal | E41: =VLOOKUP(A41,DataPublished!C:C,1,FALSE) -> 9322853147 | F41: 45668.716 | G41: rishabh.syn@gmail.com | H41: 2 | I41: 9322853147 | J41: Nandkishore Attal | K41: Kandivali - Malad Area | L41: 40459
A42: =C42 -> 9764005162 | B42: =H42 -> 2 | C42: =I42 -> 9764005162 | D42: =J42 -> Atul Bhutada | E42: =VLOOKUP(A42,DataPublished!C:C,1,FALSE) -> 9764005162 | F42: 45668.761 | G42: ajbhutada@gmail.com | H42: 2 | I42: 9764005162 | J42: Atul Bhutada | K42: Kandivali - Malad Area | L42: 5944
A43: =C43 -> 9892441866 | B43: =H43 -> 4 | C43: =I43 -> 9892441866 | D43: =J43 -> Archana Singhi | E43: =VLOOKUP(A43,DataPublished!C:C,1,FALSE) -> #N/A | F43: 45668.96 | G43: arcsinghi@gmail.com | H43: 4 | I43: 9892441866 | J43: Archana Singhi | K43: Kandivali - Malad Area | L43: 14025
... A54: =C54 -> 9324780543 | B54: =H54 -> 2 | C54: =I54 -> 9324780543 | D54: =J54 -> Rupali Biyani | E54: =VLOOKUP(A54,DataPublished!C:C,1,FALSE) -> #N/A | F54: 45699.733 | G54: biyanipankaj@gmail.com | H54: 2 | I54: 9324780543 | J54: Rupali Biyani | K54: Kandivali - Malad Area | L54: 23307
